Workbook
Name code_layer_0: Blueprint!$BR$20
Name code_layer_0: Blueprint_ep1!#REF!
Name code_layer_0: Blueprint_inference!#REF!
Name code_layer_1: Blueprint!$BR$21
Name code_layer_1: Blueprint_ep1!#REF!
Name code_layer_1: Blueprint_inference!#REF!
Name code_layer_10: Blueprint!$BR$30
Name code_layer_10: Blueprint_ep1!#REF!
Name code_layer_10: Blueprint_inference!#REF!
Name code_layer_11: Blueprint!$BR$33
Name code_layer_11: Blueprint_ep1!#REF!
Name code_layer_11: Blueprint_inference!#REF!
Name code_layer_12: Blueprint!$BR$33
Name code_layer_12: Blueprint_ep1!#REF!
Name code_layer_12: Blueprint_inference!#REF!
Name code_layer_2: Blueprint!$BR$22
Name code_layer_2: Blueprint_ep1!#REF!
Name code_layer_2: Blueprint_inference!#REF!
Name code_layer_3: Blueprint!$BR$23
Name code_layer_3: Blueprint_ep1!#REF!
Name code_layer_3: Blueprint_inference!#REF!
Name code_layer_4: Blueprint!$BR$24
Name code_layer_4: Blueprint_ep1!#REF!
Name code_layer_4: Blueprint_inference!#REF!
Name code_layer_5: Blueprint!$BR$25
Name code_layer_5: Blueprint_ep1!#REF!
Name code_layer_5: Blueprint_inference!#REF!
Name code_layer_6: Blueprint!$BR$26
Name code_layer_6: Blueprint_ep1!#REF!
Name code_layer_6: Blueprint_inference!#REF!
Name code_layer_7: Blueprint!$BR$27
Name code_layer_7: Blueprint_ep1!#REF!
Name code_layer_7: Blueprint_inference!#REF!
Name code_layer_8: Blueprint!$BR$28
Name code_layer_8: Blueprint_ep1!#REF!
Name code_layer_8: Blueprint_inference!#REF!
Name code_layer_9: Blueprint!$BR$29
Name code_layer_9: Blueprint_ep1!#REF!
Name code_layer_9: Blueprint_inference!#REF!
Name dashboard_grad_summary: Dashboard!$BC$36
Name dashboard_gradients: Dashboard!$AN$4
Name dashboard_list: Dashboard!$B$4
Name dashboard_loss: Dashboard!$K$4
Name dashboard_weights: Dashboard!$K$36
Name dW_0: Blueprint!$AM$29:$AT$32
Name dW_0: Blueprint_ep1!$AM$29:$AT$32
Name dW_0: Blueprint_inference!$AM$29:$AT$32
Name dW_3: Blueprint!$AM$69:$AQ$78
Name dW_3: Blueprint_ep1!$AM$69:$AQ$78
Name dW_3: Blueprint_inference!$AM$69:$AQ$78
Name dW_5: Blueprint!$AM$120:$AW$127
Name dW_5: Blueprint_ep1!$AM$120:$AW$127
Name dW_5: Blueprint_inference!$AM$120:$AW$127
Name dW_9: Blueprint!$AM$196:$AU$205
Name dW_9: Blueprint_ep1!$AM$196:$AU$205
Name dW_9: Blueprint_inference!$AM$196:$AU$205
Name erf_1: Blueprint!$P$37:$R$40
Name erf_1: Blueprint_ep1!$P$37:$R$40
Name erf_1: Blueprint_inference!$P$37:$R$40
Name erf_10: Blueprint!$P$210:$R$219

Sheet Architect
B1: ✍️ Architect
B4: Layers ↓ | C4: Dims ↓ | D4: Batch ↓ | G4: Backprop? ↓ | H4: Epochs ↓
A5: input ⟶ | B5: Rand | C5: 7 | D5: 3 | G5: TRUE | H5: 2 | P5: 255 | Q5: 255 | R5: 255 | S5: 255 | T5: 255 | U5: 255 | V5: 255 | W5: 255 | X5: 255 | Y5: 255 | Z5: 255 | AA5: 255 | AB5: 255 | AC5: 255 | AD5: 255 | AE5: 255 | AF5: 255 | AG5: 255 | AH5: 255 | AI5: 255 | AJ5: 255 | AK5: 255 | AL5: 255 | AM5: 255 | AN5: 255 | AO5: 255 | AP5: 255 | AQ5: 255 | AR5: 255 | AS5: 255 | AT5: 255 | AU5: 255 | AV5: 255 | AW5: 255 | AX5: 255 | AY5: 255 | AZ5: 255 | BA5: 255 | BB5: 255 | BC5: 255 | BD5: 255 | BE5: 255 | BF5: 255 | BG5: 255 | BH5: 255 | BI5: 255 | BJ5: 255 | BK5: 255
B6: Linear | C6: 4 | E6: =HYPERLINK("#Blueprint!X_0", "↓") -> ↓ | P6: 255 | Q6: 255 | R6: 255 | S6: 255 | T6: 255 | U6: 255 | V6: 255 | W6: 255 | X6: 255 | Y6: 255 | Z6: 255 | AA6: 255 | AB6: 255 | AC6: 255 | AD6: 255 | AE6: 255 | AF6: 255 | AG6: 255 | AH6: 255 | AI6: 255 | AJ6: 255 | AK6: 255 | AL6: 255 | AM6: 255 | AN6: 255 | AO6: 255 | AP6: 255 | AQ6: 255 | AR6: 255 | AS6: 255 | AT6: 255 | AU6: 255 | AV6: 255 | AW6: 255 | AX6: 255 | AY6: 255 | AZ6: 255 | BA6: 255 | BB6: 255 | BC6: 255 | BD6: 255 | BE6: 255 | BF6: 255 | BG6: 255 | BH6: 255 | BI6: 255 | BJ6: 255 | BK6: 255
B7: GELU | E7: =HYPERLINK("#Blueprint!X_1", "↓") -> ↓ | F7: ↑ | G7: =HYPERLINK("#Blueprint!X", "📌 Blueprint Tab") -> 📌 Blueprint Tab | P7: 255 | Q7: 255 | R7: 255 | S7: 255 | T7: 255 | U7: 255 | V7: 255 | W7: 255 | X7: 255 | Y7: 255 | Z7: 255 | AA7: 255 | AB7: 255 | AC7: 255 | AD7: 255 | AE7: 255 | AF7: 255 | AG7: 163 | AH7: 188 | AI7: 255 | AJ7: 255 | AK7: 255 | AL7: 255 | AM7: 236 | AN7: 186 | AO7: 255 | AP7: 255 | AQ7: 255 | AR7: 255 | AS7: 255 | AT7: 255 | AU7: 255 | AV7: 255 | AW7: 255 | AX7: 255 | AY7: 255 | AZ7: 255 | BA7: 255 | BB7: 255 | BC7: 255 | BD7: 255 | BE7: 255 | BF7: 255 | BG7: 255 | BH7: 255 | BI7: 255 | BJ7: 255 | BK7: 255
B8: Tanh | E8: =HYPERLINK("#Blueprint!X_2", "↓") -> ↓ | F8: ↑ | G8: =HYPERLINK("#Blueprint!torchcode", "📌 PyTorch Code") -> 📌 PyTorch Code | P8: 255 | Q8: 255 | R8: 255 | S8: 247 | T8: 132 | U8: 186 | V8: 255 | W8: 255 | X8: 255 | Y8: 255 | Z8: 255 | AA8: 255 | AB8: 255 | AC8: 255 | AD8: 255 | AE8: 255 | AF8: 255 | AG8: 131 | AH8: 137 | AI8: 255 | AJ8: 255 | AK8: 255 | AL8: 255 | AM8: 215 | AN8: 46 | AO8: 239 | AP8: 255 | AQ8: 255 | AR8: 204 | AS8: 222 | AT8: 255 | AU8: 255 | AV8: 255 | AW8: 255 | AX8: 255 | AY8: 255 | AZ8: 255 | BA8: 255 | BB8: 255 | BC8: 255 | BD8: 255 | BE8: 255 | BF8: 255 | BG8: 232 | BH8: 196 | BI8: 255 | BJ8: 255 | BK8: 255
B9: Linear | C9: 10 | E9: =HYPERLINK("#Blueprint!X_3", "↓") -> ↓ | F9: ↑ | G9: =HYPERLINK("#Blueprint_ep1!X", "📌 Blueprint Epoch 1 Tab") -> 📌 Blueprint Epoch 1 Tab | P9: 255 | Q9: 255 | R9: 255 | S9: 205 | T9: 5 | U9: 80 | V9: 255 | W9: 255 | X9: 255 | Y9: 255 | Z9: 255 | AA9: 255 | AB9: 255 | AC9: 255 | AD9: 255 | AE9: 255 | AF9: 255 | AG9: 156 | AH9: 128 | AI9: 255 | AJ9: 255 | AK9: 255 | AL9: 255 | AM9: 255 | AN9: 227 | AO9: 251 | AP9: 255 | AQ9: 255 | AR9: 101 | AS9: 187 | AT9: 255 | AU9: 255 | AV9: 255 | AW9: 255 | AX9: 255 | AY9: 255 | AZ9: 255 | BA9: 255 | BB9: 255 | BC9: 255 | BD9: 255 | BE9: 255 | BF9: 255 | BG9: 169 | BH9: 117 | BI9: 255 | BJ9: 255 | BK9: 255
B10: Tanh | E10: =HYPERLINK("#Blueprint!X_4", "↓") -> ↓ | F10: ↑ | G10: =HYPERLINK("#Blueprint_inference!X", "📌 Blueprint Inference Tab") -> 📌 Blueprint Inference Tab | P10: 255 | Q10: 255 | R10: 255 | S10: 157 | T10: 108 | U10: 79 | V10: 228 | W10: 255 | X10: 255 | Y10: 255 | Z10: 255 | AA10: 254 | AB10: 255 | AC10: 255 | AD10: 255 | AE10: 194 | AF10: 243 | AG10: 169 | AH10: 121 | AI10: 255 | AJ10: 255 | AK10: 227 | AL10: 252 | AM10: 255 | AN10: 254 | AO10: 255 | AP10: 255 | AQ10: 255 | AR10: 94 | AS10: 203 | AT10: 255 | AU10: 255 | AV10: 255 | AW10: 255 | AX10: 255 | AY10: 251 | AZ10: 255 | BA10: 255 | BB10: 255 | BC10: 210 | BD10: 220 | BE10: 255 | BF10: 255 | BG10: 156 | BH10: 135 | BI10: 255 | BJ10: 255 | BK10: 255
B11: Linear | C11: 8 | E11: =HYPERLINK("#Blueprint!X_5", "↓") -> ↓ | F11: ↑ | G11: =HYPERLINK("#Dashboard!A1", "📌 Dashboard Tab") -> 📌 Dashboard Tab | P11: 255 | Q11: 255 | R11: 255 | S11: 116 | T11: 178 | U11: 119 | V11: 180 | W11: 255 | X11: 215 | Y11: 197 | Z11: 232 | AA11: 53 | AB11: 163 | AC11: 255 | AD11: 182 | AE11: 4 | AF11: 153 | AG11: 186 | AH11: 116 | AI11: 255 | AJ11: 210 | AK11: 18 | AL11: 178 | AM11: 255 | AN11: 113 | AO11: 231 | AP11: 255 | AQ11: 255 | AR11: 97 | AS11: 211 | AT11: 255 | AU11: 225 | AV11: 255 | AW11: 241 | AX11: 79 | AY11: 48 | AZ11: 223 | BA11: 255 | BB11: 228 | BC11: 20 | BD11: 80 | BE11: 254 | BF11: 255 | BG11: 158 | BH11: 140 | BI11: 255 | BJ11: 230 | BK11: 248
B12: Tanh | E12: =HYPERLINK("#Blueprint!X_6", "↓") -> ↓ | F12: ↑ | G12: ✅ Done! | P12: 255 | Q12: 255 | R12: 255 | S12: 87 | T12: 220 | U12: 163 | V12: 134 | W12: 255 | X12: 163 | Y12: 118 | Z12: 125 | AA12: 69 | AB12: 82 | AC12: 255 | AD12: 71 | AE12: 131 | AF12: 142 | AG12: 192 | AH12: 113 | AI12: 255 | AJ12: 106 | AK12: 99 | AL12: 113 | AM12: 255 | AN12: 76 | AO12: 215 | AP12: 255 | AQ12: 255 | AR12: 100 | AS12: 140 | AT12: 96 | AU12: 52 | AV12: 255 | AW12: 111 | AX12: 122 | AY12: 87 | AZ12: 165 | BA12: 255 | BB12: 123 | BC12: 102 | BD12: 116 | BE12: 255 | BF12: 255 | BG12: 165 | BH12: 100 | BI12: 129 | BJ12: 28 | BK12: 208
B13: ReLU | E13: =HYPERLINK("#Blueprint!X_7", "↓") -> ↓ | F13: ↑ | P13: 255 | Q13: 255 | R13: 244 | S13: 79 | T13: 253 | U13: 209 | V13: 96 | W13: 238 | X13: 173 | Y13: 82 | Z13: 102 | AA13: 246 | AB13: 226 | AC13: 213 | AD13: 65 | AE13: 243 | AF13: 223 | AG13: 193 | AH13: 115 | AI13: 235 | AJ13: 88 | AK13: 227 | AL13: 93 | AM13: 255 | AN13: 86 | AO13: 209 | AP13: 157 | AQ13: 80 | AR13: 15 | AS13: 19 | AT13: 68 | AU13: 169 | AV13: 221 | AW13: 89 | AX13: 210 | AY13: 57 | AZ13: 220 | BA13: 249 | BB13: 61 | BC13: 220 | BD13: 217 | BE13: 185 | BF13: 104 | BG13: 31 | BH13: 10 | BI13: 49 | BJ13: 127 | BK13: 244
B14: GELU | E14: =HYPERLINK("#Blueprint!X_8", "↓") -> ↓ | F14: ↑ | P14: 255 | Q14: 255 | R14: 222 | S14: 86 | T14: 214 | U14: 138 | V14: 17 | W14: 86 | X14: 186 | Y14: 19 | Z14: 166 | AA14: 255 | AB14: 255 | AC14: 145 | AD14: 124 | AE14: 255 | AF14: 255 | AG14: 195 | AH14: 121 | AI14: 167 | AJ14: 141 | AK14: 246 | AL14: 88 | AM14: 255 | AN14: 94 | AO14: 200 | AP14: 69 | AQ14: 105 | AR14: 65 | AS14: 184 | AT14: 255 | AU14: 255 | AV14: 151 | AW14: 43 | AX14: 43 | AY14: 172 | AZ14: 255 | BA14: 206 | BB14: 75 | BC14: 255 | BD14: 255 | BE14: 114 | BF14: 78 | BG14: 96 | BH14: 116 | BI14: 255 | BJ14: 255 | BK14: 255
B15: Linear | C15: 10 | E15: =HYPERLINK("#Blueprint!X_9", "↓") -> ↓ | F15: ↑ | P15: 252 | Q15: 195 | R15: 94 | S15: 8 | T15: 17 | U15: 39 | V15: 25 | W15: 185 | X15: 192 | Y15: 12 | Z15: 230 | AA15: 255 | AB15: 255 | AC15: 95 | AD15: 183 | AE15: 255 | AF15: 246 | AG15: 193 | AH15: 120 | AI15: 108 | AJ15: 206 | AK15: 244 | AL15: 87 | AM15: 255 | AN15: 98 | AO15: 215 | AP15: 255 | AQ15: 255 | AR15: 106 | AS15: 192 | AT15: 255 | AU15: 255 | AV15: 95 | AW15: 95 | AX15: 218 | AY15: 255 | AZ15: 209 | BA15: 142 | BB15: 123 | BC15: 255 | BD15: 251 | BE15: 245 | BF15: 255 | BG15: 175 | BH15: 123 | BI15: 255 | BJ15: 255 | BK15: 255
B16: GELU | E16: =HYPERLINK("#Blueprint!X_10", "↓") -> ↓ | F16: ↑ | P16: 216 | Q16: 15 | R16: 7 | S16: 114 | T16: 213 | U16: 250 | V16: 85 | W16: 218 | X16: 189 | Y16: 67 | Z16: 255 | AA16: 255 | AB16: 252 | AC16: 72 | AD16: 223 | AE16: 255 | AF16: 135 | AG16: 181 | AH16: 100 | AI16: 92 | AJ16: 249 | AK16: 239 | AL16: 86 | AM16: 255 | AN16: 104 | AO16: 213 | AP16: 255 | AQ16: 255 | AR16: 105 | AS16: 187 | AT16: 255 | AU16: 255 | AV16: 74 | AW16: 220 | AX16: 255 | AY16: 252 | AZ16: 130 | BA16: 102 | BB16: 169 | BC16: 255 | BD16: 163 | BE16: 191 | BF16: 255 | BG16: 172 | BH16: 118 | BI16: 255 | BJ16: 255 | BK16: 255
B17: Softmax | E17: =HYPERLINK("#Blueprint!X_11", "↓") -> ↓ | F17: ↑ | P17: 246 | Q17: 214 | R17: 75 | S17: 212 | T17: 255 | U17: 255 | V17: 104 | W17: 185 | X17: 192 | Y17: 110 | Z17: 255 | AA17: 255 | AB17: 238 | AC17: 71 | AD17: 251 | AE17: 201 | AF17: 119 | AG17: 219 | AH17: 52 | AI17: 120 | AJ17: 255 | AK17: 237 | AL17: 82 | AM17: 255 | AN17: 110 | AO17: 208 | AP17: 255 | AQ17: 255 | AR17: 111 | AS17: 180 | AT17: 255 | AU17: 254 | AV17: 67 | AW17: 218 | AX17: 255 | AY17: 203 | AZ17: 126 | BA17: 97 | BB17: 204 | BC17: 244 | BD17: 92 | BE17: 241 | BF17: 255 | BG17: 179 | BH17: 112 | BI17: 255 | BJ17: 255 | BK17: 255
B18: CELoss | E18: =HYPERLINK("#Blueprint!L_12", "↓") -> ↓ | P18: 255 | Q18: 241 | R18: 64 | S18: 242 | T18: 255 | U18: 255 | V18: 126 | W18: 157 | X18: 197 | Y18: 103 | Z18: 255 | AA18: 255 | AB18: 233 | AC18: 71 | AD18: 240 | AE18: 83 | AF18: 214 | AG18: 224 | AH18: 8 | AI18: 174 | AJ18: 255 | AK18: 235 | AL18: 77 | AM18: 255 | AN18: 115 | AO18: 196 | AP18: 255 | AQ18: 255 | AR18: 120 | AS18: 168 | AT18: 255 | AU18: 255 | AV18: 70 | AW18: 166 | AX18: 248 | AY18: 87 | AZ18: 194 | BA18: 89 | BB18: 214 | BC18: 126 | BD18: 155 | BE18: 255 | BF18: 255 | BG18: 189 | BH18: 101 | BI18: 255 | BJ18: 255 | BK18: 255
P19: 255 | Q19: 196 | R19: 79 | S19: 255 | T19: 255 | U19: 255 | V19: 151 | W19: 124 | X19: 205 | Y19: 90 | Z19: 255 | AA19: 255 | AB19: 251 | AC19: 62 | AD19: 34 | AE19: 126 | AF19: 255 | AG19: 219 | AH19: 23 | AI19: 224 | AJ19: 255 | AK19: 232 | AL19: 71 | AM19: 255 | AN19: 120 | AO19: 173 | AP19: 255 | AQ19: 255 | AR19: 134 | AS19: 130 | AT19: 255 | AU19: 255 | AV19: 149 | AW19: 10 | AX19: 34 | AY19: 86 | AZ19: 255 | BA19: 117 | BB19: 34 | BC19: 75 | BD19: 249 | BE19: 255 | BF19: 255 | BG19: 206 | BH19: 70 | BI19: 254 | BJ19: 255 | BK19: 255
P20: 255 | Q20: 146 | R20: 116 | S20: 255 | T20: 255 | U20: 255 | V20: 181 | W20: 84 | X20: 228 | Y20: 143 | Z20: 255 | AA20: 255 | AB20: 255 | AC20: 189 | AD20: 128 | AE20: 249 | AF20: 255 | AG20: 215 | AH20: 63 | AI20: 252 | AJ20: 255 | AK20: 229 | AL20: 69 | AM20: 255 | AN20: 163 | AO20: 182 | AP20: 255 | AQ20: 255 | AR20: 190 | AS20: 164 | AT20: 255 | AU20: 255 | AV20: 250 | AW20: 138 | AX20: 121 | AY20: 239 | AZ20: 255 | BA20: 225 | BB20: 118 | BC20: 226 | BD20: 255 | BE20: 255 | BF20: 255 | BG20: 235 | BH20: 130 | BI20: 254 | BJ20: 255 | BK20: 255
P21: 255 | Q21: 92 | R21: 158 | S21: 255 | T21: 255 | U21: 255 | V21: 232 | W21: 166 | X21: 255 | Y21: 255 | Z21: 255 | AA21: 255 | AB21: 255 | AC21: 255 | AD21: 255 | AE21: 255 | AF21: 255 | AG21: 238 | AH21: 190 | AI21: 255 | AJ21: 255 | AK21: 249 | AL21: 211 | AM21: 255 | AN21: 254 | AO21: 254 | AP21: 255 | AQ21: 255 | AR21: 255 | AS21: 255 | AT21: 255 | AU21: 255 | AV21: 255 | AW21: 255 | AX21: 255 | AY21: 255 | AZ21: 255 | BA21: 255 | BB21: 255 | BC21: 255 | BD21: 255 | BE21: 255 | BF21: 255 | BG21: 255 | BH21: 255 | BI21: 255 | BJ21: 255 | BK21: 255
P22: 255 | Q22: 142 | R22: 216 | S22: 255 | T22: 255 | U22: 255 | V22: 255 | W22: 255 | X22: 255 | Y22: 255 | Z22: 255 | AA22: 255 | AB22: 255 | AC22: 255 | AD22: 255 | AE22: 255 | AF22: 255 | AG22: 255 | AH22: 255 | AI22: 255 | AJ22: 255 | AK22: 255 | AL22: 255 | AM22: 255 | AN22: 255 | AO22: 255 | AP22: 255 | AQ22: 255 | AR22: 255 | AS22: 255 | AT22: 255 | AU22: 255 | AV22: 255 | AW22: 255 | AX22: 255 | AY22: 255 | AZ22: 255 | BA22: 255 | BB22: 255 | BC22: 255 | BD22: 255 | BE22: 255 | BF22: 255 | BG22: 255 | BH22: 255 | BI22: 255 | BJ22: 255 | BK22: 255
P23: 255 | Q23: 255 | R23: 255 | S23: 255 | T23: 255 | U23: 255 | V23: 255 | W23: 255 | X23: 255 | Y23: 255 | Z23: 255 | AA23: 255 | AB23: 255 | AC23: 255 | AD23: 255 | AE23: 255 | AF23: 255 | AG23: 255 | AH23: 255 | AI23: 255 | AJ23: 255 | AK23: 255 | AL23: 255 | AM23: 255 | AN23: 255 | AO23: 255 | AP23: 255 | AQ23: 255 | AR23: 255 | AS23: 255 | AT23: 255 | AU23: 255 | AV23: 255 | AW23: 255 | AX23: 255 | AY23: 255 | AZ23: 255 | BA23: 255 | BB23: 255 | BC23: 255 | BD23: 255 | BE23: 255 | BF23: 255 | BG23: 255 | BH23: 255 | BI23: 255 | BJ23: 255 | BK23: 255

Sheet Blueprint
A1: =HYPERLINK("#Architect!A1", "⏎") -> ⏎ | C1: 👷🏼 Blueprint
B2: Forward ▼ | V2: Backprop ▲ | AZ2: Weight Update | BM2: PyTorch Code
P4: X=Rand
P5: -0.44880336 | Q5: 0.06070191 | R5: 0.31955508
P6: -0.11292756 | Q6: -0.27272867 | R6: 0.77663186
P7: -0.38099355 | Q7: -0.82472458 | R7: -0.20655658
P8: -0.11691222 | Q8: -0.84651675 | R8: 0.17681383
P9: -0.49264957 | Q9: 0.94102709 | R9: -0.40785891
P10: -0.88707278 | Q10: -0.34107493 | R10: 0.72421394
P11: 0.67921643 | Q11: -0.80737474 | R11: -0.96854512
P12: 1 | Q12: 1 | R12: 1
BQ13: >> | BR13: import torch
P14: target = OHE(class=10) | BQ14: >> | BR14: import torch.nn as nn
O15: Class ⟶ | P15: 5 | Q15: 8 | R15: 8 | BQ15: >>
P16: {=TRANSPOSE(--(_xlfn.SEQUENCE(1, 10) = 1+P15))} -> 0 | Q16: {=TRANSPOSE(--(_xlfn.SEQUENCE(1, 10) = 1+Q15))} -> 0 | R16: {=TRANSPOSE(--(_xlfn.SEQUENCE(1, 10) = 1+R15))} -> 0 | BO16: =HYPERLINK("#Blueprint!X","view") -> view | BQ16: >> | BR16: X = torch.randn(3, 7)
P17: 0 | Q17: 0 | R17: 0 | BO17: =HYPERLINK("#Blueprint!ohe","view") -> view | BQ17: >> | BR17: target = torch.randint(0, 10, (3,))
P18: 0 | Q18: 0 | R18: 0 | BQ18: >>
P19: 0 | Q19: 0 | R19: 0 | BQ19: >> | BR19: model = nn.Sequential(
P20: 0 | Q20: 0 | R20: 0 | BO20: =HYPERLINK("#Blueprint!X_0","view") -> view | BQ20: >> | BR20: nn.Linear(7,4),
P21: 1 | Q21: 0 | R21: 0 | BO21: =HYPERLINK("#Blueprint!X_1","view") -> view | BQ21: >> | BR21: nn.GELU(),
P22: 0 | Q22: 0 | R22: 0 | BO22: =HYPERLINK("#Blueprint!X_2","view") -> view | BQ22: >> | BR22: nn.Tanh(),
P23: 0 | Q23: 0 | R23: 0 | BO23: =HYPERLINK("#Blueprint!X_3","view") -> view | BQ23: >> | BR23: nn.Linear(4,10),
P24: 0 | Q24: 1 | R24: 1 | BO24: =HYPERLINK("#Blueprint!X_4","view") -> view | BQ24: >> | BR24: nn.Tanh(),
P25: 0 | Q25: 0 | R25: 0 | AZ25: Learning rate, 𝜂 = | BA25: 0.1 | BO25: =HYPERLINK("#Blueprint!X_5","view") -> view | BQ25: >> | BR25: nn.Linear(10,8),
BO26: =HYPERLINK("#Blueprint!X_6","view") -> view | BQ26: >> | BR26: nn.Tanh(),
A27: 0. Linear | P27: X₀ = Linear(X) | AI27: G₀=Gradient(G₁) | AT27: 𝒹W₀ | AZ27: W'₀ | BO27: =HYPERLINK("#Blueprint!X_7","view") -> view | BQ27: >> | BR27: nn.ReLU(),
N28: W₀|b₀ | P28: ✏️ X₀ = W₀ X + b₀ | AG28: ✏️ 𝒹₁=u₁/2+X₁⊙𝑒(-X₁²/2)/√(2𝜋) | AI28: ✏️ G₀ = G₁⊙𝒹₁ | AT28: ✏️ 𝒹W₀ = G₀⊙Xᵀ | AZ28: ✏️ W'₀ = W₀ − 𝜂.𝒹W₀ | BO28: =HYPERLINK("#Blueprint!X_8","view") -> view | BQ28: >> | BR28: nn.GELU(),
G29: -0.49530965 | H29: -0.82374991 | I29: 0.1545624 | J29: -0.55489147 | K29: -0.24867961 | L29: -0.94867219 | M29: -0.10543743 | N29: -0.76307999 | O29: ⟶ | P29: {=MMULT(Blueprint!G29:N32,Blueprint!P5:R12)} -> 0.45066537 | Q29: -0.051550928 | R29: -2.174642 | AE29: {=0.5*erf_1 + 0.399*X_1* EXP(-0.5*X_1^2)} -> 0.78959833 | AF29: 0.46958469 | AG29: 0.0019687597 | AH29: ⟶ | AI29: {=G_1* MaskGELU_1} -> 0.12338723 | AJ29: 0.050063558 | AK29: 0.00040850086 | AL29: ⟶ | AM29: {=MMULT(G_0, TRANSPOSE(X))} -> -0.05220711 | AN29: -0.027270332 | AO29: -0.088382764 | AP29: -0.056732887 | AQ29: -0.013842111 | AR29: -0.12623303 | AS29: 0.042990928 | AT29: 0.17385929 | AY29: ⟶ | AZ29: {=W_0 - lrate * dW_0} -> -0.49008894 | BA29: -0.82102288 | BB29: 0.16340067 | BC29: -0.54921818 | BD29: -0.24729539 | BE29: -0.93604889 | BF29: -0.10973652 | BG29: -0.78046592 | BO29: =HYPERLINK("#Blueprint!X_9","view") -> view | BQ29: >> | BR29: nn.Linear(8,10),
G30: 0.74762741 | H30: 0.98926855 | I30: 0.70640545 | J30: -0.00064654369 | K30: 0.28400189 | L30: 0.72291237 | M30: 0.19293955 | N30: -0.81849969 | O30: ⟶ | P30: -2.184955 | Q30: -1.7600501 | R30: 0.26351876 | AE30: 0.0018583015 | AF30: 0.011736745 | AG30: 0.6666246 | AH30: ⟶ | AI30: 0.00051480485 | AJ30: 0.0027383413 | AK30: 0.36716997 | AL30: ⟶ | AM30: 0.1172662 | AN30: 0.28435093 | AO30: -0.078295887 | AP30: 0.062542488 | AQ30: -0.14743031 | AR30: 0.26451896 | AS30: -0.35748188 | AT30: 0.37042311 | AY30: ⟶ | AZ30: 0.73590079 | BA30: 0.96083346 | BB30: 0.71423504 | BC30: -0.0069007925 | BD30: 0.29874492 | BE30: 0.69646048 | BF30: 0.22868774 | BG30: -0.855542 | BO30: =HYPERLINK("#Blueprint!X_10","view") -> view | BQ30: >> | BR30: nn.GELU()
G31: -0.7195804 | H31: 0.90017655 | I31: 0.84911089 | J31: 0.77893791 | K31: 0.10101674 | L31: -0.6389669 | M31: 0.10017095 | N31: -0.48206641 | O31: ⟶ | P31: -0.090262148 | Q31: -1.8987973 | R31: -0.65153803 | AE31: 0.44734191 | AF31: 0.0070120519 | AG31: 0.19138193 | AH31: ⟶ | AI31: -0.095414387 | AJ31: -0.0025146506 | AK31: -0.11323 | AL31: ⟶ | AM31: 0.0064864311 | AN31: -0.076477296 | AO31: 0.061814563 | AP31: -0.0067368281 | AQ31: 0.090821369 | AR31: 0.0034944433 | AS31: 0.046891613 | AT31: -0.21115904 | AY31: ⟶ | AZ31: -0.72022905 | BA31: 0.90782428 | BB31: 0.84292944 | BC31: 0.7796116 | BD31: 0.091934603 | BE31: -0.63931634 | BF31: 0.095481786 | BG31: -0.4609505 | BQ31: >> | BR31: )
G32: 0.88624333 | H32: 0.64300196 | I32: -0.68941218 | J32: 0.65878942 | K32: -0.06615542 | L32: -0.87859024 | M32: -0.95508953 | N32: 0.074577545 | O32: ⟶ | P32: -0.046890584 | Q32: 0.97243425 | R32: 1.4317847 | T32: =HYPERLINK("#Blueprint!torchcode", "</>") -> </> | V32: =HYPERLINK("#Blueprint!torchcode", "</>") -> </> | AE32: 0.4722977 | AF32: 1.0675404 | AG32: 1.1439352 | AH32: ⟶ | AI32: -0.024778914 | AJ32: 0.028735496 | AK32: 0.0055748388 | AL32: ⟶ | AM32: 0.014646627 | AN32: -0.00070917397 | AO32: -0.015409783 | AP32: -0.020442412 | AQ32: 0.036974454 | AR32: 0.016217119 | AS32: -0.045430042 | AT32: 0.0095314208 | AY32: ⟶ | AZ32: 0.88477866 | BA32: 0.64307288 | BB32: -0.6878712 | BC32: 0.66083366 | BD32: -0.069852866 | BE32: -0.88021196 | BF32: -0.95054652 | BG32: 0.073624403 | BQ32: >>
T33: =HYPERLINK("#X", "▲") -> ▲ | V33: =HYPERLINK("#X", "▲") -> ▲ | BO33: =HYPERLINK("#Blueprint!L_12","view") -> view | BQ33: >> | BR33: loss_fn = nn.CrossEntropyLoss()
P34: ↓ | Q34: ↓ | R34: ↓ | AI34: ↑ | AJ34: ↑ | AK34: ↑ | BQ34: >> | BR34: # Forward pass
A35: 1. GELU | P35: X₁ = GELU(X₀) | AI35: G₁=Gradient(G₂) | BO35: =HYPERLINK("#Blueprint!X_11","view") -> view | BQ35: >> | BR35: X_out = model(X)
P36: ✏️ u₁ = 1+erf(X₀/√2) | AG36: ✏️ 𝒹₂=1-X₂² | AI36: ✏️ G₁=𝒹₂⊙𝒹₂ | BO36: =HYPERLINK("#Blueprint!L_12","view") -> view | BQ36: >> | BR36: L = loss_fn(X_out, target)
P37: {=1+ERF(Blueprint!P29:R32/SQRT(2))} -> 1.3477693 | Q37: 0.95888652 | R37: 0.029656953 | AE37: {=_xlfn.DROP(1-(X_2*X_2),-1)} -> 0.91315678 | AF37: 0.99938938 | AG37: 0.99896088 | AH37: ⟶ | AI37: {=G_2*MaskTanh_2} -> 0.15626582 | AJ37: 0.10661242 | AK37: 0.20749147 | BQ37: >>
P38: 0.028892148 | Q38: 0.078399307 | R38: 1.2078492 | AE38: 0.99900437 | AF38: 0.99525498 | AG38: 0.97509431 | AH38: ⟶ | AI38: 0.27702977 | AJ38: 0.23331352 | AK38: 0.5507897 | BQ38: >> | BR38: # === Training Loop ===
P39: 0.9280789 | Q39: 0.057591133 | R39: 0.51469924 | AE39: 0.99824768 | AF39: 0.99701638 | AG39: 0.97240441 | AH39: ⟶ | AI39: -0.21329186 | AJ39: -0.35861837 | AK39: -0.59164416 | BQ39: >> | BR39: num_epochs = 2
P40: 0.96260043 | Q40: 1.6691654 | R40: 1.8477945 | AE40: 0.99949084 | AF40: 0.55048447 | AG40: 0.24747151 | AH40: ⟶ | AI40: -0.052464609 | AJ40: 0.026917479 | AK40: 0.0048733871 | BQ40: >> | BR40: optimizer = torch.optim.SGD(
P41: ✏️ X₁ = 0.5X₀ ⊙ u1 | BQ41: >> | BR41: model.parameters(), lr=0.1)
...

Sheet Blueprint_ep1
A1: =HYPERLINK("#Architect!A1", "⏎") -> ⏎ | C1: 👷🏼 Blueprint | K1: Epoch-1
B2: Forward ▼ | V2: Backprop ▲ | AZ2: Weight Update
P4: X=Rand
P5: -0.44880336 | Q5: 0.06070191 | R5: 0.31955508
P6: -0.11292756 | Q6: -0.27272867 | R6: 0.77663186
P7: -0.38099355 | Q7: -0.82472458 | R7: -0.20655658
P8: -0.11691222 | Q8: -0.84651675 | R8: 0.17681383
P9: -0.49264957 | Q9: 0.94102709 | R9: -0.40785891
P10: -0.88707278 | Q10: -0.34107493 | R10: 0.72421394
P11: 0.67921643 | Q11: -0.80737474 | R11: -0.96854512
P12: 1 | Q12: 1 | R12: 1
P14: target = OHE(class=10)
O15: Class ⟶ | P15: 5 | Q15: 8 | R15: 8
P16: {=TRANSPOSE(--(_xlfn.SEQUENCE(1, 10) = 1+P15))} -> 0 | Q16: {=TRANSPOSE(--(_xlfn.SEQUENCE(1, 10) = 1+Q15))} -> 0 | R16: {=TRANSPOSE(--(_xlfn.SEQUENCE(1, 10) = 1+R15))} -> 0
P17: 0 | Q17: 0 | R17: 0
P18: 0 | Q18: 0 | R18: 0
P19: 0 | Q19: 0 | R19: 0
P20: 0 | Q20: 0 | R20: 0
P21: 1 | Q21: 0 | R21: 0
P22: 0 | Q22: 0 | R22: 0
P23: 0 | Q23: 0 | R23: 0
P24: 0 | Q24: 1 | R24: 1
P25: 0 | Q25: 0 | R25: 0 | AZ25: Learning rate, 𝜂 = | BA25: =Blueprint!lrate -> 0.1
A27: 0. Linear | P27: X₀ = Linear(X) | AI27: G₀=Gradient(G₁) | AT27: 𝒹W₀ | AZ27: W'₀
N28: W₀|b₀ | P28: ✏️ X₀ = W₀ X + b₀ | AG28: ✏️ 𝒹₁=u₁/2+X₁⊙𝑒(-X₁²/2)/√(2𝜋) | AI28: ✏️ G₀ = G₁⊙𝒹₁ | AT28: ✏️ 𝒹W₀ = G₀⊙Xᵀ | AZ28: ✏️ W'₀ = W₀ − 𝜂.𝒹W₀
G29: {=Blueprint!newW_0} -> -0.49008894 | H29: -0.82102288 | I29: 0.16340067 | J29: -0.54921818 | K29: -0.24729539 | L29: -0.93604889 | M29: -0.10973652 | N29: -0.78046592 | O29: ⟶ | P29: {=MMULT(Blueprint_ep1!G29:N32,Blueprint_ep1!P5:R12)} -> 0.41179807 | Q29: -0.0809873 | R29: -2.176323 | AE29: {=0.5*erf_1 + 0.399*X_1* EXP(-0.5*X_1^2)} -> 0.76423128 | AF29: 0.4526228 | AG29: 0.0019504622 | AH29: ⟶ | AI29: {=G_1* MaskGELU_1} -> -0.0065433467 | AJ29: 0.048815857 | AK29: 0.0001579903 | AL29: ⟶ | AM29: {=MMULT(G_0, TRANSPOSE(X))} -> 0.0059503784 | AN29: -0.01245186 | AO29: -0.037799298 | AP29: -0.040530509 | AQ29: 0.049096183 | AR29: -0.010731022 | AS29: -0.044010059 | AT29: 0.042430501 | AY29: ⟶ | AZ29: {=W_0 - lrate * dW_0} -> -0.49068398 | BA29: -0.81977769 | BB29: 0.1671806 | BC29: -0.54516513 | BD29: -0.25220501 | BE29: -0.93497578 | BF29: -0.10533552 | BG29: -0.78470897
G30: 0.73590079 | H30: 0.96083346 | I30: 0.71423504 | J30: -0.0069007925 | K30: 0.29874492 | L30: 0.69646048 | M30: 0.22868774 | N30: -0.855542 | O30: ⟶ | P30: -2.1752927 | Q30: -1.7971786 | R30: 0.13812882 | AE30: 0.0019616631 | AF30: 0.010283458 | AG30: 0.5854251 | AH30: ⟶ | AI30: 8.3532507e-06 | AJ30: 0.0027169188 | AK30: 0.16858653 | AL30: ⟶ | AM30: 0.054033853 | AN30: 0.13018774 | AO30: -0.037066548 | AP30: 0.027507535 | AQ30: -0.066206938 | AR30: 0.12115863 | AS30: -0.16547156 | AT30: 0.1713118 | AY30: ⟶ | AZ30: 0.73049741 | BA30: 0.94781468 | BB30: 0.71794169 | BC30: -0.009651546 | BD30: 0.30536562 | BE30: 0.68434462 | BF30: 0.2452349 | BG30: -0.87267318
G31: -0.72022905 | H31: 0.90782428 | I31: 0.84292944 | J31: 0.7796116 | K31: 0.091934603 | L31: -0.63931634 | M31: 0.095481786 | N31: -0.4609505 | O31: ⟶ | P31: -0.065843099 | Q31: -1.8799202 | R31: -0.61530117 | AE31: 0.46131131 | AF31: 0.0075481894 | AG31: 0.20399357 | AH31: ⟶ | AI31: 0.018310617 | AJ31: -0.0033916767 | AK31: -0.063040414 | AL31: ⟶ | AM31: -0.028568632 | AN31: -0.05010196 | AO31: 0.0088423844 | AP31: -0.010416041 | AQ31: 0.013499218 | AR31: -0.060740781 | AS31: 0.076232712 | AT31: -0.048121474 | AY31: ⟶ | AZ31: -0.71737218 | BA31: 0.91283448 | BB31: 0.8420452 | BC31: 0.7806532 | BD31: 0.090584681 | BE31: -0.63324226 | BF31: 0.087858515 | BG31: -0.45613836
G32: 0.88477866 | H32: 0.64307288 | I32: -0.6878712 | J32: 0.66083366 | K32: -0.069852866 | L32: -0.88021196 | M32: -0.95054652 | N32: 0.073624403 | O32: ⟶ | P32: -0.041674685 | Q32: 0.96177732 | R32: 1.4263952 | T32: =HYPERLINK("#Blueprint!torchcode", "</>") -> </> | V32: =HYPERLINK("#Blueprint!torchcode", "</>") -> </> | AE32: 0.47534293 | AF32: 1.0637187 | AG32: 1.1439145 | AH32: ⟶ | AI32: 0.014523591 | AJ32: -0.025369963 | AK32: 0.013487767 | AL32: ⟶ | AM32: -0.0037481573 | AN32: 0.015754032 | AO32: 0.01260385 | AP32: 0.022162937 | AQ32: -0.036529969 | AR32: 0.0055376046 | AS32: 0.017284218 | AT32: 0.0026413948 | AY32: ⟶ | AZ32: 0.88515348 | BA32: 0.64149747 | BB32: -0.68913159 | BC32: 0.65861737 | BD32: -0.066199869 | BE32: -0.88076572 | BF32: -0.95227495 | BG32: 0.073360263
T33: =HYPERLINK("#X", "▲") -> ▲ | V33: =HYPERLINK("#X", "▲") -> ▲
P34: ↓ | Q34: ↓ | R34: ↓ | AI34: ↑ | AJ34: ↑ | AK34: ↑
A35: 1. GELU | P35: X₁ = GELU(X₀) | AI35: G₁=Gradient(G₂)
P36: ✏️ u₁ = 1+erf(X₀/√2) | AG36: ✏️ 𝒹₂=1-X₂² | AI36: ✏️ G₁=𝒹₂⊙𝒹₂
P37: {=1+ERF(Blueprint_ep1!P29:R32/SQRT(2))} -> 1.3195126 | Q37: 0.93545205 | R37: 0.02953112 | AE37: {=_xlfn.DROP(1-(X_2*X_2),-1)} -> 0.92967251 | AF37: 0.99856649 | AG37: 0.99896808 | AH37: ⟶ | AI37: {=G_2*MaskTanh_2} -> -0.0085619981 | AJ37: 0.10785108 | AK37: 0.081001468
P38: 0.029608189 | Q38: 0.072307263 | R38: 1.1098614 | AE38: 0.99896367 | AF38: 0.99579016 | AG38: 0.99414742 | AH38: ⟶ | AI38: 0.0042582494 | AJ38: 0.26420284 | AK38: 0.28797284
P39: 0.94750274 | Q39: 0.060118948 | R39: 0.53835584 | AE39: 0.99902761 | AF39: 0.99681347 | AG39: 0.97306218 | AH39: ⟶ | AI39: 0.039692538 | AJ39: -0.44933645 | AK39: -0.30903137
P40: 0.96675804 | Q40: 1.6638385 | R40: 1.8462457 | AE40: 0.9995943 | AF40: 0.55896528 | AG40: 0.25009523 | AH40: ⟶ | AI40: 0.030553923 | AJ40: -0.023850256 | AK40: 0.011790887
P41: ✏️ X₁ = 0.5X₀ ⊙ u1
P42: {=0.5*Blueprint_ep1!P29:R32*Blueprint_ep1!P37:R40} -> 0.27168637 | Q42: -0.037879868 | R42: -0.032134628
P43: -0.032203239 | Q43: -0.064974535 | R43: 0.076651922
...

Sheet Blueprint_inference
A1: =HYPERLINK("#Architect!A1", "⏎") -> ⏎ | C1: 👷🏼 Blueprint | K1: Inference
B2: Forward ▼
P4: X=Rand
P5: -0.44880336 | Q5: 0.06070191 | R5: 0.31955508
P6: -0.11292756 | Q6: -0.27272867 | R6: 0.77663186
P7: -0.38099355 | Q7: -0.82472458 | R7: -0.20655658
P8: -0.11691222 | Q8: -0.84651675 | R8: 0.17681383
P9: -0.49264957 | Q9: 0.94102709 | R9: -0.40785891
P10: -0.88707278 | Q10: -0.34107493 | R10: 0.72421394
P11: 0.67921643 | Q11: -0.80737474 | R11: -0.96854512
P12: 1 | Q12: 1 | R12: 1
P14: target = OHE(class=10)
O15: Class ⟶ | P15: 5 | Q15: 8 | R15: 8
P16: {=TRANSPOSE(--(_xlfn.SEQUENCE(1, 10) = 1+P15))} -> 0 | Q16: {=TRANSPOSE(--(_xlfn.SEQUENCE(1, 10) = 1+Q15))} -> 0 | R16: {=TRANSPOSE(--(_xlfn.SEQUENCE(1, 10) = 1+R15))} -> 0
P17: 0 | Q17: 0 | R17: 0
P18: 0 | Q18: 0 | R18: 0
P19: 0 | Q19: 0 | R19: 0
P20: 0 | Q20: 0 | R20: 0
P21: 1 | Q21: 0 | R21: 0
P22: 0 | Q22: 0 | R22: 0
P23: 0 | Q23: 0 | R23: 0
P24: 0 | Q24: 1 | R24: 1
P25: 0 | Q25: 0 | R25: 0
A27: 0. Linear | P27: X₀ = Linear(X)
N28: W₀|b₀ | P28: ✏️ X₀ = W₀ X + b₀
G29: {=Blueprint!newW_0} -> -0.49008894 | H29: -0.82102288 | I29: 0.16340067 | J29: -0.54921818 | K29: -0.24729539 | L29: -0.93604889 | M29: -0.10973652 | N29: -0.78046592 | O29: ⟶ | P29: {=MMULT(Blueprint_inference!G29:N32,Blueprint_inference!P5:R12)} -> 0.41179807 | Q29: -0.0809873 | R29: -2.176323
G30: 0.73590079 | H30: 0.96083346 | I30: 0.71423504 | J30: -0.0069007925 | K30: 0.29874492 | L30: 0.69646048 | M30: 0.22868774 | N30: -0.855542 | O30: ⟶ | P30: -2.1752927 | Q30: -1.7971786 | R30: 0.13812882
G31: -0.72022905 | H31: 0.90782428 | I31: 0.84292944 | J31: 0.7796116 | K31: 0.091934603 | L31: -0.63931634 | M31: 0.095481786 | N31: -0.4609505 | O31: ⟶ | P31: -0.065843099 | Q31: -1.8799202 | R31: -0.61530117
G32: 0.88477866 | H32: 0.64307288 | I32: -0.6878712 | J32: 0.66083366 | K32: -0.069852866 | L32: -0.88021196 | M32: -0.95054652 | N32: 0.073624403 | O32: ⟶ | P32: -0.041674685 | Q32: 0.96177732 | R32: 1.4263952 | T32: =HYPERLINK("#Blueprint!torchcode", "</>") -> </>
T33: =HYPERLINK("#X", "▲") -> ▲
P34: ↓ | Q34: ↓ | R34: ↓
A35: 1. GELU | P35: X₁ = GELU(X₀)
P36: ✏️ u₁ = 1+erf(X₀/√2)
P37: {=1+ERF(Blueprint_inference!P29:R32/SQRT(2))} -> 1.3195126 | Q37: 0.93545205 | R37: 0.02953112
P38: 0.029608189 | Q38: 0.072307263 | R38: 1.1098614
P39: 0.94750274 | Q39: 0.060118948 | R39: 0.53835584
P40: 0.96675804 | Q40: 1.6638385 | R40: 1.8462457
P41: ✏️ X₁ = 0.5X₀ ⊙ u1
P42: {=0.5*Blueprint_inference!P29:R32*Blueprint_inference!P37:R40} -> 0.27168637 | Q42: -0.037879868 | R42: -0.032134628
P43: -0.032203239 | Q43: -0.064974535 | R43: 0.076651922
...

Sheet Dashboard
A1: =HYPERLINK("#Architect!A1", "⏎") -> ⏎ | B1: 🎬 Dashboard
C4: Visualizations | L4: Loss | AF4: =HYPERLINK("#Dashboard!dashboard_list", "↩ List") -> ↩ List | AO4: Gradient Flow | CJ4: =HYPERLINK("#Dashboard!dashboard_list", "↩ List") -> ↩ List
C5: =HYPERLINK("#Dashboard!dashboard_loss", "Loss") -> Loss | K5: Epochs | L5: Loss
C6: =HYPERLINK("#Dashboard!dashboard_gradients", "Gradient Flow") -> Gradient Flow | K6: {=_xlfn.SEQUENCE(2, 1, 0)} -> 0 | L6: =Blueprint!LossMean -> 2.3186953 | AP6: Gradients
C7: =HYPERLINK("#Dashboard!dashboard_weights", "Weight Update") -> Weight Update | K7: 1 | L7: =Blueprint_ep1!LossMean -> 1.9741135 | AP7: ⟶ ⟶ ⟶ ⟶
C8: =HYPERLINK("#Dashboard!dashboard_grad_summary", "Mean gradient") -> Mean gradient | AN8: Epochs | AP8: G₁₂ (ep:0) | AT8: G₁₁ (ep:0) | AX8: G₁₀ (ep:0) | BB8: G₉ (ep:0) | BF8: G₈ (ep:0) | BJ8: G₇ (ep:0) | BN8: G₆ (ep:0) | BR8: G₅ (ep:0) | BV8: G₄ (ep:0) | BZ8: G₃ (ep:0) | CD8: G₂ (ep:0) | CH8: G₁ (ep:0)
AN9: ↓ | AP9: {=Blueprint!G_11} -> 0 | AQ9: 0 | AR9: 0 | AT9: {=Blueprint!G_10} -> 0.075941863 | AU9: 0.065432054 | AV9: 0.059701832 | AX9: {=Blueprint!G_9} -> 0.019346229 | AY9: 0.011558453 | AZ9: 0.016284735 | BB9: {=Blueprint!G_8} -> 0.29088839 | BC9: 0.96639231 | BD9: 1.0339844 | BF9: {=Blueprint!G_7} -> 0.15071853 | BG9: 0.48319616 | BH9: 0.52657913 | BJ9: {=Blueprint!G_6} -> 0.15071853 | BK9: 0 | BL9: 0.52657913 | BN9: {=Blueprint!G_5} -> 0.15058232 | BO9: 0 | BP9: 0.52645375 | BR9: {=Blueprint!G_4} -> -0.086390004 | BS9: 0.034218301 | BT9: -0.090132616 | BV9: {=Blueprint!G_3} -> -0.075957732 | BW9: 0.025384148 | BX9: -0.045810211 | BZ9: {=Blueprint!G_2} -> 0.17112704 | CA9: 0.10667756 | CB9: 0.20770731 | CD9: {=Blueprint!G_1} -> 0.15626582 | CE9: 0.10661242 | CF9: 0.20749147 | CH9: {=Blueprint!G_0} -> 0.12338723 | CI9: 0.050063558 | CJ9: 0.00040850086
AN10: ↓ | AP10: 0 | AQ10: 0 | AR10: 0 | AT10: 0.16320457 | AU10: 0.16468133 | AV10: 0.15424273 | AX10: 0.16090116 | AY10: 0.17244516 | AZ10: 0.16427369 | BB10: 0.061623101 | BC10: 0.64566756 | BD10: 0.70944982 | BF10: 0.036679939 | BG10: 0.63733385 | BH10: 0.73407332 | BJ10: 0.036679939 | BK10: 0.63733385 | BL10: 0.73407332 | BN10: 0.035815672 | BO10: 0.24426857 | BP10: 0.15509679 | BR10: -0.11846294 | BS10: 0.17890338 | BT10: -0.23360683 | BV10: -0.072645779 | BW10: 0.028829325 | BX10: -0.025194686 | BZ10: 0.27730587 | CA10: 0.23442587 | CB10: 0.56485788 | CD10: 0.27702977 | CE10: 0.23331352 | CF10: 0.5507897 | CH10: 0.00051480485 | CI10: 0.0027383413 | CJ10: 0.36716997
AN11: ↓ | AP11: 0 | AQ11: 0 | AR11: 0 | AT11: 0.074632037 | AU11: 0.078783269 | AV11: 0.081159982 | AX11: 0.013178995 | AY11: 0.040913295 | AZ11: 0.054312459 | BB11: 0.066301197 | BC11: 0.028103364 | BD11: 0.083410794 | BF11: 0.033150598 | BG11: 0.018586215 | BH11: 0.060311008 | BJ11: 0 | BK11: 0.018586215 | BL11: 0.060311008 | BN11: 0 | BO11: 0.017373098 | BP11: 0.052956303 | BR11: 0.051859871 | BS11: 0.1097077 | BT11: 0.11583912 | BV11: 0.045266931 | BW11: 0.074302107 | BX11: 0.069107713 | BZ11: -0.21366627 | CA11: -0.35969155 | CB11: -0.60843427 | CD11: -0.21329186 | CE11: -0.35861837 | CF11: -0.59164416 | CH11: -0.095414387 | CI11: -0.0025146506 | CJ11: -0.11323
AP12: 0 | AQ12: 0 | AR12: 0 | AT12: 0.11838158 | AU12: 0.08071275 | AV12: 0.064500042 | AX12: 0.092396205 | AY12: 0.044125414 | AZ12: 0.02654377 | BB12: -0.045656407 | BC12: -0.36230256 | BD12: -0.3946957 | BF12: -0.024667467 | BG12: -0.19903913 | BH12: -0.19734785 | BJ12: -0.024667467 | BK12: -0.19903913 | BL12: 0 | BN12: -0.02455937 | BO12: -0.19773805 | BP12: 0 | BR12: -0.092863813 | BS12: 0.079280431 | BT12: -0.20792445 | BV12: -0.072789456 | BW12: 0.018104383 | BX12: -0.055510574 | BZ12: -0.052491336 | CA12: 0.0488978 | CB12: 0.01969272 | CD12: -0.052464609 | CE12: 0.026917479 | CF12: 0.0048733871 | CH12: -0.024778914 | CI12: 0.028735496 | CJ12: 0.0055748388
AP13: 0 | AQ13: 0 | AR13: 0 | AT13: 0.076463551 | AU13: 0.0699265 | AV13: 0.064684315 | AX13: 0.020876179 | AY13: 0.024981014 | AZ13: 0.026884046 | BB13: 0.071369965 | BC13: 0.0015407639 | BD13: -0.049794259 | BF13: 0.035684983 | BG13: 0.00077038194 | BH13: -0.02489713 | BJ13: 0 | BK13: 0 | BL13: 0 | BN13: 0 | BO13: 0 | BP13: 0 | BR13: -0.085036333 | BS13: -0.31567298 | BT13: -0.33898485 | BV13: -0.038905788 | BW13: -0.22484677 | BX13: -0.30116921 | BZ13: G₃ (ep:1) | CD13: G₂ (ep:1) | CH13: G₁ (ep:1)
AP14: -12.802504 | AQ14: 0 | AR14: 0 | AT14: -0.92189028 | AU14: 0.066005572 | AV14: 0.058244922 | AX14: -0.041470265 | AY14: 0.0066786844 | AZ14: 0.0097045616 | BB14: -0.033286682 | BC14: 0.27427016 | BD14: 0.2246546 | BF14: -0.035350409 | BG14: 0.23914564 | BH14: 0.1423694 | BJ14: -0.035350409 | BK14: 0.23914564 | BL14: 0.1423694 | BN14: -0.0029702956 | BO14: 0.1585385 | BP14: 0.13589985 | BR14: -0.18310006 | BS14: -0.33216854 | BT14: -0.66220954 | BV14: -0.11714369 | BW14: -0.15547288 | BX14: -0.21056327 | BZ14: {=Blueprint_ep1!G_2} -> -0.0092096926 | CA14: 0.10800591 | CB14: 0.081085142 | CD14: {=Blueprint_ep1!G_1} -> -0.0085619981 | CE14: 0.10785108 | CF14: 0.081001468 | CH14: {=Blueprint_ep1!G_0} -> -0.0065433467 | CI14: 0.048815857 | CJ14: 0.0001579903
AP15: 0 | AQ15: 0 | AR15: 0 | AT15: 0.074580703 | AU15: 0.068241713 | AV15: 0.063162388 | AX15: 0.011804679 | AY15: 0.021333283 | AZ15: 0.024006476 | BB15: -0.11805946 | BC15: 0.3168971 | BD15: 0.35446443 | BF15: -0.059029732 | BG15: 0.15844855 | BH15: 0.17723221 | BJ15: 0 | BK15: 0 | BL15: 0 | BN15: 0 | BO15: 0 | BP15: 0 | BR15: -0.0019886447 | BS15: 0.01750248 | BT15: -0.041607854 | BV15: -0.001986236 | BW15: 0.0096899576 | BX15: -0.020436801 | BZ15: 0.0042626669 | CA15: 0.26531979 | CB15: 0.28966814 | CD15: 0.0042582494 | CE15: 0.26420284 | CF15: 0.28797284 | CH15: 8.3532507e-06 | CI15: 0.0027169188 | CJ15: 0.16858653
AP16: 0 | AQ16: 0 | AR16: 0 | AT16: 0.085992825 | AU16: 0.06546416 | AV16: 0.058281906 | AX16: 0.040067007 | AY16: 0.011921504 | AZ16: 0.0082609903 | BB16: -0.024907437 | BC16: -0.34105638 | BD16: -0.33764919 | BF16: -0.022951588 | BG16: -0.35095786 | BH16: -0.340698 | BJ16: -0.022951588 | BK16: -0.35095786 | BL16: -0.340698 | BN16: -0.012838609 | BO16: -0.082335977 | BP16: -0.10567044 | BR16: -0.10384976 | BS16: -0.10307433 | BT16: -0.39651152 | BV16: -0.092980526 | BW16: -0.065955727 | BX16: -0.22954451 | BZ16: 0.039731172 | CA16: -0.45077285 | CB16: -0.31758646 | CD16: 0.039692538 | CE16: -0.44933645 | CF16: -0.30903137 | CH16: 0.018310617 | CI16: -0.0033916767 | CJ16: -0.063040414
AP17: 0 | AQ17: -8.898638 | AR17: -9.2123689 | AT17: 0.11993992 | AU17: -0.88762325 | AV17: -0.89145029 | AX17: 0.09483875 | AY17: -0.74571901 | AZ17: -0.79778503 | BB17: G₉ (ep:1) | BF17: G₈ (ep:1) | BJ17: G₇ (ep:1) | BN17: G₆ (ep:1) | BR17: 0.14900038 | BS17: 0.40285153 | BT17: 0.66758184 | BV17: 0.14109967 | BW17: 0.31910629 | BX17: 0.49823233 | BZ17: 0.030566323 | CA17: -0.042668583 | CB17: 0.047145589 | CD17: 0.030553923 | CE17: -0.023850256 | CF17: 0.011790887 | CH17: 0.014523591 | CI17: -0.025369963 | CJ17: 0.013487767
AP18: 0 | AQ18: 0 | AR18: 0 | AT18: 0.13275324 | AU18: 0.2283759 | AV18: 0.28747217 | AX18: 0.1147726 | AY18: 0.25775253 | AZ18: 0.32828408 | BB18: {=Blueprint_ep1!G_8} -> 0.15720323 | BC18: 0.98184252 | BD18: 1.0335634 | BF18: {=Blueprint_ep1!G_7} -> 0.078601613 | BG18: 0.49092126 | BH18: 0.51678171 | BJ18: {=Blueprint_ep1!G_6} -> 0 | BK18: 0 | BL18: 0 | BN18: {=Blueprint_ep1!G_5} -> 0 | BO18: 0 | BP18: 0 | BR18: 0.18428809 | BS18: 0.12063265 | BT18: 0.51148911 | BV18: 0.1476465 | BW18: 0.11765235 | BX18: 0.44254541
AP19: G₁₂ (ep:1) | AT19: G₁₁ (ep:1) | AX19: G₁₀ (ep:1) | BB19: -0.012631056 | BC19: 0.5425881 | BD19: 0.58940919 | BF19: -0.0063155281 | BG19: 0.48016716 | BH19: 0.57053231 | BJ19: 0 | BK19: 0.48016716 | BL19: 0.57053231 | BN19: 0 | BO19: 0.30617968 | BP19: 0.2512327 | BR19: G₅ (ep:1) | BV19: G₄ (ep:1)
AP20: {=Blueprint_ep1!G_11} -> 0 | AQ20: 0 | AR20: 0 | AT20: {=Blueprint_ep1!G_10} -> 0.075354521 | AU20: 0.066168264 | AV20: 0.062216757 | AX20: {=Blueprint_ep1!G_9} -> 0.017080782 | AY20: 0.014089534 | AZ20: 0.019060051 | BB20: 0.086254415 | BC20: -0.051993198 | BD20: -0.0035481285 | BF20: 0.043127207 | BG20: -0.033913924 | BH20: -0.0025017019 | BJ20: 0 | BK20: -0.033913924 | BL20: -0.0025017019 | BN20: 0 | BO20: -0.031934067 | BP20: -0.0022424132 | BR20: {=Blueprint_ep1!G_4} -> -0.011841266 | BS20: 0.038900278 | BT20: 0.0072257374 | BV20: {=Blueprint_ep1!G_3} -> -0.010592222 | BW20: 0.029366244 | BX20: 0.0040929223
AP21: 0 | AQ21: 0 | AR21: 0 | AT21: 0.1347568 | AU21: 0.13131081 | AV21: 0.12126591 | AX21: 0.11778652 | AY21: 0.12300563 | AZ21: 0.11466819 | BB21: 0.0070173707 | BC21: -0.39926043 | BD21: -0.43921387 | BF21: 0.0047966267 | BG21: -0.28799751 | BH21: -0.24372979 | BJ21: 0.0047966267 | BK21: -0.28799751 | BL21: -0.24372979 | BN21: 0.0043953174 | BO21: -0.25340377 | BP21: -0.24176637 | BR21: -0.013386302 | BS21: 0.21738756 | BT21: 0.14611073 | BV21: -0.0079122335 | BW21: 0.034043612 | BX21: 0.015380081
AP22: 0 | AQ22: 0 | AR22: 0 | AT22: 0.074698734 | AU22: 0.072890859 | AV22: 0.078561974 | AX22: 0.010625214 | AY22: 0.03007821 | AZ22: 0.048107531 | BB22: 0.048569543 | BC22: -0.013339227 | BD22: -0.064630171 | BF22: 0.024284771 | BG22: -0.0066696135 | BH22: -0.032315086 | BJ22: 0 | BK22: 0 | BL22: 0 | BN22: 0 | BO22: 0 | BP22: 0 | BR22: 0.010050532 | BS22: 0.081411695 | BT22: 0.10057307 | BV22: 0.0089847642 | BW22: 0.057671218 | BX22: 0.062217973
AP23: 0 | AQ23: 0 | AR23: 0 | AT23: 0.10589839 | AU23: 0.072767013 | AV23: 0.064843759 | AX23: 0.072598852 | AY23: 0.029848831 | AZ23: 0.02462973 | BB23: -0.082162929 | BC23: 0.33180103 | BD23: 0.26669765 | BF23: -0.086756293 | BG23: 0.26209126 | BH23: 0.15258788 | BJ23: -0.086756293 | BK23: 0.26209126 | BL23: 0.15258788 | BN23: -0.009972563 | BO23: 0.20874918 | BP23: 0.15049318 | BR23: 0.0029248158 | BS23: 0.071658202 | BT23: 0.036809676 | BV23: 0.0021890977 | BW23: 0.015963111 | BX23: 0.0086591211
AP24: 0 | AQ24: 0 | AR24: 0 | AT24: 0.075955843 | AU24: 0.069694832 | AV24: 0.064051547 | AX24: 0.019200473 | AY24: 0.023805305 | AZ24: 0.02305467 | BB24: -0.14551994 | BC24: 0.41184552 | BD24: 0.44779694 | BF24: -0.07275997 | BG24: 0.20592276 | BH24: 0.22389847 | BJ24: 0 | BK24: 0 | BL24: 0 | BN24: 0 | BO24: 0 | BP24: 0 | BR24: 0.0078788512 | BS24: -0.35328716 | BT24: -0.33644473 | BV24: 0.0033298657 | BW24: -0.22911647 | BX24: -0.26615436
AP25: -12.739633 | AQ25: 0 | AR25: 0 | AT25: -0.9215048 | AU25: 0.066251537 | AV25: 0.059853468 | AX25: -0.038093724 | AY25: 0.0071062631 | AZ25: 0.0083689644 | BB25: 0.029573371 | BC25: -0.48879655 | BD25: -0.46523227 | BF25: 0.0289421 | BG25: -0.51321377 | BH25: -0.48618146 | BJ25: 0.0289421 | BK25: -0.51321377 | BL25: -0.48618146 | BN25: 0.011841557 | BO25: -0.073717902 | BP25: -0.080877513 | BR25: 0.0093061329 | BS25: -0.4259906 | BT25: -0.34879088 | BV25: 0.0062174191 | BW25: -0.21580672 | BX25: -0.13696274
AP26: 0 | AQ26: 0 | AR26: 0 | AT26: 0.075227596 | AU26: 0.065906399 | AV26: 0.061490523 | AX26: 0.00798104 | AY26: 0.012558673 | AZ26: 0.017237852 | BR26: 0.014080492 | BS26: 0.022531059 | BT26: -0.0044277682 | BV26: 0.014005898 | BW26: 0.012319778 | BX26: -0.0021859465
AP27: 0 | AQ27: 0 | AR27: 0 | AT27: 0.087862652 | AU27: 0.06650963 | AV27: 0.059820358 | AX27: 0.043195912 | AY27: 0.015521046 | AZ27: 0.0087727176 | BR27: 0.0097550963 | BS27: -0.11638098 | BT27: -0.13070859 | BV27: 0.0084308865 | BW27: -0.06955602 | BX27: -0.071117542
AP28: 0 | AQ28: -5.1963666 | AR28: -5.6387532 | AT28: 0.1744199 | AU28: -0.80755784 | AV28: -0.82265583 | AX28: 0.17731014 | AY28: -0.88387772 | AZ28: -0.90317499 | BR28: -0.018511234 | BS28: 0.55716369 | BT28: 0.4321275 | BV28: -0.018326051 | BW28: 0.3798721 | BX28: 0.27422348
AP29: 0 | AQ29: 0 | AR29: 0 | AT29: 0.11733036 | AU29: 0.1960585 | AV29: 0.25055154 | AX29: 0.090665414 | AY29: 0.21549882 | AZ29: 0.2863788 | BR29: -0.0043270717 | BS29: 0.11686374 | BT29: 0.15658328 | BV29: -0.0033234274 | BW29: 0.11637247 | BX29: 0.14868855
L36: Weight Update | AV36: =HYPERLINK("#Dashboard!dashboard_list", "↩ List") -> ↩ List | BD36: Mean Gradient | BW36: =HYPERLINK("#Dashboard!dashboard_list", "↩ List") -> ↩ List
M38: Weights | BD38: Ep | BE38: G₀ | BF38: G₁ | BG38: G₂ | BH38: G₃ | BI38: G₄ | BJ38: G₅ | BK38: G₆ | BL38: G₇ | BM38: G₈ | BN38: G₉ | BO38: G₁₀ | BP38: G₁₁
M39: ⟶ ⟶ ⟶ ⟶ | BD39: {=_xlfn.SEQUENCE(2,1,0)} -> 0 | BE39: {=IFERROR(SUMPRODUCT(ABS(Blueprint!G_0))/COUNT(Blueprint!G_0),"")} -> 0.067877557 | BF39: {=IFERROR(SUMPRODUCT(ABS(Blueprint!G_1))/COUNT(Blueprint!G_1),"")} -> 0.23160938 | BG39: {=IFERROR(SUMPRODUCT(ABS(Blueprint!G_2))/COUNT(Blueprint!G_2),"")} -> 0.23874796 | BH39: {=IFERROR(SUMPRODUCT(ABS(Blueprint!G_3))/COUNT(Blueprint!G_3),"")} -> 0.12479603 | BI39: {=IFERROR(SUMPRODUCT(ABS(Blueprint!G_4))/COUNT(Blueprint!G_4),"")} -> 0.200558 | BJ39: {=IFERROR(SUMPRODUCT(ABS(Blueprint!G_5))/COUNT(Blueprint!G_5),"")} -> 0.079295733 | BK39: {=IFERROR(SUMPRODUCT(ABS(Blueprint!G_6))/COUNT(Blueprint!G_6),"")} -> 0.14664423 | BL39: {=IFERROR(SUMPRODUCT(ABS(Blueprint!G_7))/COUNT(Blueprint!G_7),"")} -> 0.19538413 | BM39: {=IFERROR(SUMPRODUCT(ABS(Blueprint!G_8))/COUNT(Blueprint!G_8),"")} -> 0.28485108 | BN39: {=IFERROR(SUMPRODUCT(ABS(Blueprint!G_9))/COUNT(Blueprint!G_9),"")} -> 0.11344734 | BO39: {=IFERROR(SUMPRODUCT(ABS(Blueprint!G_10))/COUNT(Blueprint!G_10),"")} -> 0.18006425 | BP39: {=IFERROR(SUMPRODUCT(ABS(Blueprint!G_11))/COUNT(Blueprint!G_11),"")} -> 1.0304504
K40: Epochs | M40: 𝒹W₀ (ep:0) | V40: 𝒹W₃ (ep:0) | AB40: 𝒹W₅ (ep:0) | AN40: 𝒹W₉ (ep:0) | BD40: 1 | BE40: {=IFERROR(SUMPRODUCT(ABS(Blueprint_ep1!G_0))/COUNT(Blueprint_ep1!G_0),"")} -> 0.030412752 | BF40: {=IFERROR(SUMPRODUCT(ABS(Blueprint_ep1!G_1))/COUNT(Blueprint_ep1!G_1),"")} -> 0.13484199 | BG40: {=IFERROR(SUMPRODUCT(ABS(Blueprint_ep1!G_2))/COUNT(Blueprint_ep1!G_2),"")} -> 0.14050186 | BH40: {=IFERROR(SUMPRODUCT(ABS(Blueprint_ep1!G_3))/COUNT(Blueprint_ep1!G_3),"")} -> 0.074436078 | BI40: {=IFERROR(SUMPRODUCT(ABS(Blueprint_ep1!G_4))/COUNT(Blueprint_ep1!G_4),"")} -> 0.12678129 | BJ40: {=IFERROR(SUMPRODUCT(ABS(Blueprint_ep1!G_5))/COUNT(Blueprint_ep1!G_5),"")} -> 0.067783592 | BK40: {=IFERROR(SUMPRODUCT(ABS(Blueprint_ep1!G_6))/COUNT(Blueprint_ep1!G_6),"")} -> 0.13139216 | BL40: {=IFERROR(SUMPRODUCT(ABS(Blueprint_ep1!G_7))/COUNT(Blueprint_ep1!G_7),"")} -> 0.20229207 | BM40: {=IFERROR(SUMPRODUCT(ABS(Blueprint_ep1!G_8))/COUNT(Blueprint_ep1!G_8),"")} -> 0.29585375 | BN40: {=IFERROR(SUMPRODUCT(ABS(Blueprint_ep1!G_9))/COUNT(Blueprint_ep1!G_9),"")} -> 0.11344605 | BO40: {=IFERROR(SUMPRODUCT(ABS(Blueprint_ep1!G_10))/COUNT(Blueprint_ep1!G_10),"")} -> 0.17011457 | BP40: {=IFERROR(SUMPRODUCT(ABS(Blueprint_ep1!G_11))/COUNT(Blueprint_ep1!G_11),"")} -> 0.78582508
K41: ↓ | M41: {=Blueprint!dW_0} -> -0.05220711 | N41: -0.027270332 | O41: -0.088382764 | P41: -0.056732887 | Q41: -0.013842111 | R41: -0.12623303 | S41: 0.042990928 | T41: 0.17385929 | V41: {=Blueprint!dW_3} -> -0.021534663 | W41: -0.0065813839 | X41: 0.0094030549 | Y41: -0.021006633 | Z41: -0.096383795 | AB41: {=Blueprint!dW_5} -> -0.42150152 | AC41: 0.59090241 | AD41: 0.38806802 | AE41: 0.5207452 | AF41: 0.28674399 | AG41: -0.52514919 | AH41: 0.38076992 | AI41: 0.39033934 | AJ41: -0.23048031 | AK41: 0.12613625 | AL41: 0.67703607 | AN41: {=Blueprint!dW_9} -> 0.00042495754 | AO41: 0.020535676 | AP41: 0.0053940135 | AQ41: 0.0011714981 | AR41: 0 | AS41: 0.022236691 | AT41: 0 | AU41: 0.028548533 | AV41: 0.047189417
K42: ↓ | M42: 0.1172662 | N42: 0.28435093 | O42: -0.078295887 | P42: 0.062542488 | Q42: -0.14743031 | R42: 0.26451896 | S42: -0.35748188 | T42: 0.37042311 | V42: -0.021308341 | W42: -0.0036697589 | X42: 0.0056515954 | Y42: -0.00088787693 | Z42: -0.06901114 | AB42: -0.24532112 | AC42: 0.39249172 | AD42: 0.25004663 | AE42: 0.36401433 | AF42: 0.20920673 | AG42: -0.3277391 | AH42: 0.27507738 | AI42: 0.25881605 | AJ42: -0.18124092 | AK42: 0.079365791 | AL42: 0.43518104 | AN42: 0.0037595474 | AO42: 0.2385852 | AP42: 0.062985179 | AQ42: 0.013027083 | AR42: 0 | AS42: 0.22039948 | AT42: 0 | AU42: 0.31054575 | AV42: 0.49762001
K43: ↓ | M43: 0.0064864311 | N43: -0.076477296 | O43: 0.061814563 | P43: -0.0067368281 | Q43: 0.090821369 | R43: 0.0034944433 | S43: 0.046891613 | T43: -0.21115904 | V43: 0.0092760135 | W43: 0.004359694 | X43: -0.017433593 | Y43: 0.10874493 | Z43: 0.18867675 | AB43: -0.045962772 | AC43: 0.065931016 | AD43: 0.043504723 | AE43: 0.060600613 | AF43: 0.027006258 | AG43: -0.056404998 | AH43: 0.049381802 | AI43: 0.044789632 | AJ43: -0.034593199 | AK43: 0.022172964 | AL43: 0.070329402 | AN43: 0.00062704029 | AO43: 0.065523819 | AP43: 0.018352826 | AQ43: 0.0022197393 | AR43: 0 | AS43: 0.034328371 | AT43: 0 | AU43: 0.071442636 | AV43: 0.10840475
M44: 0.014646627 | N44: -0.00070917397 | O44: -0.015409783 | P44: -0.020442412 | Q44: 0.036974454 | R44: 0.016217119 | S44: -0.045430042 | T44: 0.0095314208 | V44: -0.020108414 | W44: -0.0077107605 | X44: 0.011279484 | Y44: -0.034373819 | Z44: -0.11019565 | AB44: 0.10900608 | AC44: -0.19637995 | AD44: -0.12108979 | AE44: -0.18511791 | AF44: -0.12415501 | AG44: 0.15895962 | AH44: -0.13296485 | AI44: -0.12660713 | AJ44: 0.084501348 | AK44: -0.020129425 | AL44: -0.22229742 | AN44: 0.0016294397 | AO44: 0.054279216 | AP44: 0.012673383 | AQ44: 0.0051183487 | AR44: 0 | AS44: 0.095193228 | AT44: 0 | AU44: 0.094595828 | AV44: 0.16306539
M45: 𝒹W₀ (ep:1) | V45: 0.0037992368 | W45: -0.030813149 | X45: 0.063940311 | Y45: -0.41113216 | Z45: -0.56492177 | AB45: 0 | AC45: 0 | AD45: 0 | AE45: 0 | AF45: 0 | AG45: 0 | AH45: 0 | AI45: 0 | AJ45: 0 | AK45: 0 | AL45: 0 | AN45: 0.0005312893 | AO45: 0.036580879 | AP45: 0.0098103929 | AQ45: 0.0018023856 | AR45: 0 | AS45: 0.030378367 | AT45: 0 | AU45: 0.045824287 | AV45: 0.07274124
M46: {=Blueprint_ep1!dW_0} -> 0.0059503784 | N46: -0.01245186 | O46: -0.037799298 | P46: -0.040530509 | Q46: 0.049096183 | R46: -0.010731022 | S46: -0.044010059 | T46: 0.042430501 | V46: -0.023891828 | W46: -0.018824214 | X46: 0.048374643 | Y46: -0.28425519 | Z46: -0.48317984 | AB46: -0.17482126 | AC46: 0.27171903 | AD46: 0.17532201 | AE46: 0.25423737 | AF46: 0.12824242 | AG46: -0.2260797 | AH46: 0.20275716 | AI46: 0.18236472 | AJ46: -0.14141567 | AK46: 0.076137515 | AL46: 0.29146806 | AN46: -0.00056249884 | AO46: 0.0075450015 | AP46: 0.0031823204 | AQ46: -0.0011576819 | AR46: 0 | AS46: -0.028973843 | AT46: 0 | AU46: -0.0094007031 | AV46: -0.025087019
M47: 0.054033853 | N47: 0.13018774 | O47: -0.037066548 | P47: 0.027507535 | Q47: -0.066206938 | R47: 0.12115863 | S47: -0.16547156 | T47: 0.1713118 | V47: -0.00016598352 | W47: -0.0038300524 | X47: 0.0029488003 | Y47: -0.011187058 | Z47: -0.012733079 | AB47: 0 | AC47: 0 | AD47: 0 | AE47: 0 | AF47: 0 | AG47: 0 | AH47: 0 | AI47: 0 | AJ47: 0 | AK47: 0 | AL47: 0 | AN47: 0.00036918977 | AO47: 0.031477143 | AP47: 0.0086108396 | AQ47: 0.0013293189 | AR47: 0 | AS47: 0.021284266 | AT47: 0 | AU47: 0.036841725 | AV47: 0.057144439
M48: -0.028568632 | N48: -0.05010196 | O48: 0.0088423844 | P48: -0.010416041 | Q48: 0.013499218 | R48: -0.060740781 | S48: 0.076232712 | T48: -0.048121474 | V48: -0.018371307 | W48: -0.028748486 | X48: 0.04562665 | Y48: -0.24124874 | Z48: -0.38848076 | AB48: 0.12039776 | AC48: -0.1832047 | AD48: -0.11846857 | AE48: -0.16876742 | AF48: -0.088914736 | AG48: 0.15502495 | AH48: -0.13083273 | AI48: -0.12213405 | AJ48: 0.087806143 | AK48: -0.046012434 | AL48: -0.20084503 | AN48: 0.00068121607 | AO48: 0.016751913 | AP48: 0.0036662019 | AQ48: 0.0019091535 | AR48: 0 | AS48: 0.037863104 | AT48: 0 | AU48: 0.033763686 | AV48: 0.060249502
M49: -0.0037481573 | N49: 0.015754032 | O49: 0.01260385 | P49: 0.022162937 | Q49: -0.036529969 | R49: 0.0055376046 | S49: 0.017284218 | T49: 0.0026413948 | V49: 0.017634815 | W49: 0.052195177 | X49: -0.10610288 | Y49: 0.64297245 | Z49: 0.95843828 | AB49: 𝒹W₅ (ep:1) | AN49: -0.0047711873 | AO49: -1.0267372 | AP49: -0.29180015 | AQ49: -0.028783677 | AR49: 0 | AS49: -0.33537125 | AT49: 0 | AU49: -1.0089434 | AV49: -1.4486653
...

Sheet tinyDigits
C1: Dataset | D1: tinyDigits | J1: =OFFSET(Helper!J13,0,1) -> 2 | Z1: DO NOT CHANGE ANYTHING IN THIS TAB!
C2: 0 | J2: 1 | Q2: 2 | X2: 3 | AE2: 4 | AL2: 5 | AS2: 6 | AZ2: 7 | BG2: 8 | BN2: 9 | BU2: 10 | CE2: Metadata
B3: 0 | C3: Original | J3: {=INDEX(Helper!$E$13:$E$22, OFFSET(Helper!$J$13,$B3,J$2))} -> Vertical Flip | Q3: {=INDEX(Helper!$E$13:$E$22, OFFSET(Helper!$J$13,$B3,Q$2))} -> Shift Right | X3: {=INDEX(Helper!$E$13:$E$22, OFFSET(Helper!$J$13,$B3,X$2))} -> 90 CCW | AE3: {=INDEX(Helper!$E$13:$E$22, OFFSET(Helper!$J$13,$B3,AE$2))} -> Shift Up | AL3: {=INDEX(Helper!$E$13:$E$22, OFFSET(Helper!$J$13,$B3,AL$2))} -> Shift Down | AS3: {=INDEX(Helper!$E$13:$E$22, OFFSET(Helper!$J$13,$B3,AS$2))} -> Shift Left | AZ3: {=INDEX(Helper!$E$13:$E$22, OFFSET(Helper!$J$13,$B3,AZ$2))} -> 180 Rotation | BG3: {=INDEX(Helper!$E$13:$E$22, OFFSET(Helper!$J$13,$B3,BG$2))} -> Noise | BN3: {=INDEX(Helper!$E$13:$E$22, OFFSET(Helper!$J$13,$B3,BN$2))} -> Horizontal Flip | BU3: {=INDEX(Helper!$E$13:$E$22, OFFSET(Helper!$J$13,$B3,BU$2))} -> 90 CW | CD3: class | CE3: 10
